Workbook
Name _____xlnm.Print_Area: #REF!
Name _____xlnm.Print_Area_1: #REF!
Name _____xlnm.Print_Titles: #REF!
Name ____xlnm.Print_Area: #REF!
Name ____xlnm.Print_Area_1: #REF!
Name ____xlnm.Print_Titles: #REF!
Name ___xlnm.Print_Area: #REF!
Name ___xlnm.Print_Area_1: #REF!
Name ___xlnm.Print_Titles: #REF!
Name __xlnm.Print_Area: #REF!
Name __xlnm.Print_Area_1: #REF!
Name __xlnm.Print_Area_2: #REF!
Name __xlnm.Print_Area_3: #REF!
Name __xlnm.Print_Area_4: #REF!
Name __xlnm.Print_Area_6: #REF!
Name __xlnm.Print_Titles: #REF!
Name a: #REF!
Name a_kl: #REF!
Name B: #REF!
Name b_kl: #REF!
Name evro: #REF!
Name Excel_BuiltIn_Print_Area: #REF!
Name gbp: #REF!
Name k: #REF!
Name korr_mo: #REF!
Name m: #REF!
Name non: #REF!
Name ord: #REF!
Name PCc: #REF!
Name PKf: #REF!
Name PSl: #REF!
Name roz: #REF!
Name roza: #REF!
Name s: #REF!
Name usd: #REF!
Name а: #REF!
Name асном: #REF!
Name б: #REF!
Name ВалютнаяЦена: #REF!
Name вес: #REF!
Name Возврат: '[1]смр с нач'!$D$36
Name ЗЛа: #REF!
Name ключи: "#REF!"
Name ключи_1: "#REF!"
Name КодБазы: #REF!
Name Кол_во_в_уп_Kc: #REF!
Name Кол_во_в_уп_Sl: #REF!
Name Кол_во_в_уп_Stl: #REF!
Name Кол_во_в_уп_Сс: #REF!
Name МелкийОпт: #REF!
Name ПалетаKc: #REF!
Name ПалетаSl: #REF!
Name ПалетаStL: #REF!
Name ПалетаСс: #REF!
Name Паллета: #REF!
Name р: #REF!
Name ррр: #REF!
Name ррррррр: #REF!
Name т1: #REF!
Name тег: #REF!

Sheet КС2 №1
J1: Форма № КС-2
J2: Код
A4: Заказчик | B4: АО «МСУ-1», 140005, Московская обл., г.Люберцы, ул. Комсомольская, дом.15А, эт.11, помещение 19, ИНН 7745000111, КПП 502701001 | J4: 52570646
B5: организация, адрес, телефон, факс | I5: по ОКПО
A6: Исполнитель | B6: ООО "ВЭЛЛДАН", 119311, Москва г, пр-т Вернадского, д.15 кв.268, ИНН 7736328072, КПП 773601001 | J6: 44333671
B7: организация, адрес, телефон, факс | I7: по ОКПО
A8: Стройка: | B8: выполнение дополнительного комплекса работ по монтажу, пуско-наладке и сдаче наружных сетей связи на объекте капитального строительства: «Комплексная реконструкция, реставрация и приспособление зданий бывшей городской усадьбы XVIII-XIX вв. (г. Москва, ул. Волхонка, д. 8, строения 7, 8, 9, 10, 11) под музейно-административные здания».
A9: Объект: | B9: «Комплексная реконструкция, реставрация и приспособление зданий бывшей городской усадьбы XVIII-XIX вв. (г. Москва, ул. Волхонка, д. 8, строения 7, 8, 9, 10, 11) под музейно-административные здания».
B10: наименование, адрес
I11: Вид деятельности по ОКВЭД | J11: 42.22
H12: Договор подряда | I12: номер | J12: ППК-ЕЗ/Волх8/112/23_СП
I13: дата | J13: 46045
G14: Дополнительное соглашение | I14: номер | J14: 2
I15: дата | J15: 46132
G16: Номер документа | H16: Дата составления | I16: Отчетный период
I17: с | J17: по
E18: АКТ | G18: 1 | H18: 46178 | I18: 46143 | J18: 46169
A19: О ПРИЕМКЕ ВЫПОЛНЕННЫХ РАБОТ
A20: № п/п | B20: Наименование видов работ, оборудования, затрат | C20: Ед. изм. | D20: Кол-во | E20: Стоимость единицы работ | F20: Твердая договорная стоимость, руб | G20: Выполнено с начала строительства | I20: Выполнено за отчетный период
G21: Кол-во | H21: Стоимость итого с НДС, руб | I21: Кол-во | J21: Стоимость итого с НДС, руб
A22: 1 | B22: 2 | C22: 3 | D22: 4 | E22: 5 | F22: 6 | G22: 7 | H22: 8 | I22: 9 | J22: 10
B23: Лот №1 - г. Москва, ул. Волхонка, д.8, строения 7, 8, 9, 10, 11 - Монтаж, пуско-наладка и сдача наружных сетей связи | M23: Наружные сети связи. НСС
A24: 1 | B24: Наружные сети связи 112/23-ВЛХ-Р-НСС | M24: Земляные работы | N24: 61.2 | O24: 3250 | Q24: =B24=M24 -> FALSE | R24: =D25-N24 -> -61.2 | S24: =E25-O24 -> -3250 | V24: =I25*E25 -> 0
A25: 2 | B25: Земляные работы | M25: Разработка траншеи, котлована, с механизацией, ручная доработка | N25: 26.01 | O25: 2194.17 | Q25: =B25=M25 -> FALSE | R25: =D26-N25 -> 26.99 | S25: =E26-O25 -> 1705.83 | V25: =I26*E26 -> 0
A26: 3 | B26: Разработка траншеи, котлована, с механизацией, ручная доработка в отвал | C26: м3 | D26: 53 | E26: 3900 | F26: =D26*E26 -> 206700 | G26: 0 | H26: =D26*E26 -> 206700 | J26: =G26*D26 -> 0 | M26: Засыпка песчаным грунтом (песчаное основание и засыпка с уплотнением Ку=0,95) | N26: 24.77 | O26: 750 | Q26: =B26=M26 -> FALSE | R26: =D27-N26 -> -13.27 | S26: =E27-O26 -> 2450 | V26: =I27*E27 -> 0
A27: 4 | B27: Песок (песчаное основание и засыпка с уплотнением) | C27: м3 | D27: 11.5 | E27: 3200 | F27: =D27*E27 -> 36800 | G27: 0 | H27: =D27*E27 -> 36800 | J27: =G27*D27 -> 0 | M27: Обратная засыпка траншей грунтом с послойным уплотнением Ку=0,95 | N27: 11.4 | O27: 7500 | Q27: =B27=M27 -> FALSE | R27: =D28-N27 -> 26.6 | S27: =E28-O27 -> -6300 | V27: =I28*E28 -> 0
A28: 5 | B28: Засыпка траншей грунтом с послойным уплотнением Ку=0,95 | C28: м3 | D28: 38 | E28: 1200 | F28: =D28*E28 -> 45600 | G28: 0 | H28: =D28*E28 -> 45600 | J28: =G28*D28 -> 0 | M28: Разборка а/б покрытий проездов и улиц | Q28: =B28=M28 -> FALSE | R28: =D29-N28 -> 4 | S28: =E29-O28 -> 35500 | V28: =I29*E29 -> 0
A29: 6 | B29: Шурфление для геодезической съемки | C29: м3 | D29: 4 | E29: 35500 | F29: =D29*E29 -> 142000 | G29: 4 | J29: =G29*D29 -> 16 | M29: Канализация связи | V29: =I30*E30 -> 0
A30: 7 | B30: Телефонная канализация | F30: =D30*E30 -> 0 | M30: Монтаж колодцев | N30: 3 | O30: 113070 | Q30: =B29=M29 -> FALSE | R30: =D30-N30 -> -3 | S30: =E30-O30 -> -113070 | V30: =I31*E31 -> 0
A31: 8 | B31: Монтаж колодцев сетей связи | C31: шт | D31: 3 | E31: 113894.67 | F31: =D31*E31-0.01 -> 341684 | G31: 0 | H31: =D31*E31 -> 341684.01 | J31: 341684 | M31: Гидроизоляция телефонных колодцев в два слоя | N31: 19 | O31: 1047.62 | Q31: =B30=M30 -> FALSE | R31: =D31-N31 -> -16 | S31: =E31-O31 -> 112847.05 | V31: =I32*E32 -> 0
A32: 9 | B32: Монтаж кабельной канализации | C32: м | D32: 40.5 | E32: 4894.9 | F32: =D32*E32 -> 198243.45 | G32: 0 | H32: =D32*E32 -> 198243.45 | J32: 198243.6 | M32: Организация ввода в колодец (2 канала) | N32: 8 | O32: 1750 | Q32: =B31=M31 -> FALSE | R32: =D32-N32 -> 32.5 | S32: =E32-O32 -> 3144.9 | V32: =I33*E33 -> 0
A33: 10 | B33: Труба ПНД ПЭ100 SDR11 PN16 DN50х3мм | C33: м | D33: 120 | E33: 0 | F33: =D33*E33 -> 0 | G33: 0 | J33: =(G33*D33)/1.2*0.98360656 -> 0 | M33: Организация ввода в здание (2 канала) | N33: 2 | O33: 21750 | Q33: =B32=M32 -> FALSE | R33: =D33-N33 -> 118 | S33: =E33-O33 -> -21750 | V33: =I34*E34 -> 0
A34: 11 | B34: Кластер ССД-Пайп 110611-00010 OD50 мм тройной ( арт: 110611-00010) | C34: шт | D34: 30 | E34: 0 | F34: =D34*E34 -> 0 | G34: 0 | J34: =(G34*D34)/1.2*0.98360656 -> 0 | M34: Монтаж кабельной канализации | N34: 60.7 | O34: 4535.56 | Q34: =B33=M33 -> FALSE | R34: =D34-N34 -> -30.7 | S34: =E34-O34 -> -4535.56 | V34: =I35*E35 -> 0
A35: 12 | B35: Уплотнитель кабельных проходов термоусаживаемый УКПт 115/34 цвет черный ( арт: 120317-00425) | C35: шт (0.33 м) | D35: 3 | E35: 0 | F35: =D35*E35 -> 0 | G35: 0 | J35: =(G35*D35)/1.2*0.98360656 -> 0 | M35: Гидроизоляция стальных футляров в два слоя | N35: 35.8 | O35: 1064.28 | Q35: =B34=M34 -> FALSE | R35: =D35-N35 -> -32.8 | S35: =E35-O35 -> -1064.28 | V35: =I36*E36 -> 0
A36: 13 | B36: Труба ввода ТВВК ССД 110608-00034 D=57мм ( арт: 110608-00034) | C36: шт | D36: 3 | E36: 0 | F36: =D36*E36 -> 0 | G36: 0 | J36: =(G36*D36)/1.2*0.98360656 -> 0 | M36: Кабельные линии | Q36: =B35=M35 -> FALSE | R36: =D36-N36 -> 3 | S36: =E36-O36 -> 0 | V36: =I37*E37 -> 0
A37: 14 | B37: Каболка канализационная КБЮ1010 10-12мм 10кг | C37: шт | D37: 4.2 | E37: 0 | F37: =D37*E37 -> 0 | G37: 0 | J37: =(G37*D37)/1.2*0.98360656 -> 0 | M37: Прокладка кабельных линий | N37: 1455 | O37: 359.12 | Q37: =B36=M36 -> FALSE | R37: =D37-N37 -> -1450.8 | S37: =E37-O37 -> -359.12 | V37: =I38*E38 -> 0
A38: 15 | B38: Гидроизоляция в два слоя | C38: м | D38: 15 | E38: 948 | F38: =D38*E38 -> 14220 | G38: 0 | J38: =G38*D38 -> 0 | M38: Монтаж оптического кросса | N38: 4 | O38: 57233.33 | Q38: =B37=M37 -> FALSE | R38: =D38-N38 -> 11 | S38: =E38-O38 -> -56285.33 | V38: =I39*E39 -> 0
A39: 16 | B39: Кабельные линии | F39: =D39*E39 -> 0 | M39: Гидроизоляция стальных футляров в два слоя | N39: 2 | O39: 5784.17 | Q39: =B38=M38 -> FALSE | R39: =D39-N39 -> -2 | S39: =E39-O39 -> -5784.17 | V39: =#REF!*#REF! -> #REF!
A40: 17 | B40: Протяжка кабельной трассы | C40: м | D40: 2605 | E40: 743.22 | F40: =D40*E40 -> 1936088.1 | G40: 0 | H40: =D40*E40 -> 1936088.1 | J40: 1936094
A41: 18 | B41: Монтаж компрессионной муфты | C41: шт | D41: 4 | E41: 46829 | F41: =D41*E41 -> 187316 | G41: 0 | J41: =D41*G41 -> 0
...

Sheet КС3 №1
I1: Форма № КС-3
H2: Код
G3: Форма по ОКУД | H3: 0322001
H4: 52570646
A5: Заказчик | B5: ООО «СМУ-17», 143005, Московская обл.,Одинцовский р-н, пос. Трехгорка, ул. Трехгорная, дом.4, помещение 315, ИНН 5032273578, КПП 503201001 | G5: по ОКПО
B6: организация, адрес, телефон, факс | H6: 44333671
A7: Исполнитель | B7: ООО "ВЭЛЛДАН", 119311, Москва г, пр-т Вернадского, д.15 кв.268, ИНН 7736328072, КПП 773601001 | G7: по ОКПО
B8: организация, адрес, телефон, факс
A10: Стройка | B10: ='КС2 №1'!B8:H8 -> выполнение дополнительного комплекса работ по монтажу, пуско-наладке и сдаче наружных сетей связи на объекте капитального строительства: «Комплексная реконструкция, реставрация и приспособление зданий бывшей городской усадьбы XVIII-XIX вв. (г. Москва, ул. Волхонка, д. 8, строения 7, 8, 9, 10, 11) под музейно-административные здания».
B11: наименование, адрес
A12: Объект | B12: «Конноспортивный манеж» по адресу: г. Москва, проспект Мира, д. 119
B13: наименование, адрес
G14: Вид деятельности по ОКВЭД | H14: 42.22
F15: Договор подряда | G15: номер | H15: 4012-СМР
G16: дата | H16: 45943
E17: Дополнительное соглашение | G17: номер | H17: 2
G18: дата | H18: 46132
G19: Вид операции
F21: Номер документа | G21: Дата составления | H21: Отчетный период
H22: с | I22: по
F23: ='КС2 №1'!G18 -> 1 | G23: ='КС2 №1'!H18 -> 46178 | H23: ='КС2 №1'!I18 -> 46143 | I23: =G23 -> 46178
A25: СПРАВКА
A26: СТОИМОСТИ ВЫПОЛНЕННЫХ РАБОТ И ЗАТРАТ
A28: № п/п | B28: Наименование видов работ, оборудования, затрат | F28: Код | G28: Стоимость выполненных работ и затрат, руб.
G29: с начала проведения работ | H29: с начала года | I29: в том числе за отчетный период
A30: 1 | B30: 2 | F30: 3 | G30: 4 | H30: 5 | I30: 6
A31: 1. | B31: Всего работ и затрат, включаемых в стоимость работ | G31: =G33 -> #REF! | H31: =H33 -> #REF! | I31: =I32 -> #REF!
A32: 1.1 | B32: СМР | G32: =G33 -> #REF! | H32: =H33 -> #REF! | I32: =I33 -> #REF! | K32: 2431645.1
A33: Итого | G33: =I33 -> #REF! | H33: =I33 -> #REF! | I33: =I35-I34 -> #REF! | K33: 534961.92
A34: НДС 22% | G34: =I34 -> 536755.03 | H34: =I34 -> 536755.03 | I34: ='КС2 №1'!J70 -> 536755.03 | K34: 2966607
A35: Всего с учетом НДС | G35: =I35 -> #REF! | H35: =I35 -> #REF! | I35: ='КС2 №1'!#REF! -> #REF! | K35: 148330.35
A36: Гарантийное удержание 5% | G36: =ROUND(0.05*G35,2) -> #REF! | H36: =ROUND(0.05*H35,2) -> #REF! | I36: =ROUND(0.05*I35,2) -> #REF!
A37: Услуги генерального подряда 1% | K37: 800000
A38: Погашение аванса | I38: 800000
A39: Удержание штрафных санкций
A40: Удержание за материалы
A41: Удержание за оказанные услуги | K41: 2018276.6
A42: Итого к оплате | I42: =I35-I36-I38 -> #REF! | K42: 363951.53
A43: В т.ч. НДС 22% | I43: =I42/122*22 -> #REF!
A50: Субподрядчик:
...
